<?xml version="1.0"?>
<!-- 
Author: Uriel Ortiz   
E-Mail: euriel.ortiz@gmail.com    
Date:   august/2016

This is the main XML code for the Golem URDF.
URDF allow to simulate accurately geometry and kinematics of a robot
with programs like gazebo or rviz.
-->

<robot
    name="golem"
    xmlns:xacro="http://www.ros.org/wiki/xacro">


    <!-- Constants for robot dimensions -->
    <xacro:property name="PI" value="3.1415926535897931"/>
    <xacro:property name="FRICTION" value="0.4"/>
    <xacro:property name="JOINT_VEL" value="0.5"/>
    <xacro:property name="CONTROLLER" value="EffortJointInterface"/>


    <!-- Import all Gazebo-customization elements, including Gazebo colors -->
    <xacro:include filename="$(find golem_description)/urdf/golem.gazebo" />

    <!-- Used for fixing robot to Gazebo 'base_link' -->
    <link name="world"/>    

    <!-- Base link -->
   <link
    name="base_link">
    <inertial>
      <origin
        xyz="0.0 0.0 0.0"
        rpy="0 0 0" />
    <mass
      value="2" />
    <inertia
      ixx="0.002"  ixy="0.0000"   ixz="0.0000"
      iyy="0.002"  iyz="0.0000"
      izz="0.002" />
    </inertial>

    <visual>
      <origin
        xyz="0 0 0"
        rpy="0 0 0" />
      <geometry>
        <mesh
          filename="package://golem_description/meshes/base_link.STL" />
      </geometry>
      <material
        name="">
        <color
          rgba="0.5 0.5 1 1" />
      </material>
    </visual>

    <collision>
      <origin
        xyz="0 0 0"
        rpy="0 0 0" />
      <geometry>
        <mesh
          filename="package://golem_description/meshes/base_link.STL" />
      </geometry>
    </collision>
  </link>

  <joint name="fixed_joint" type="fixed">
      <parent link="world"/>
      <child link="base_link"/>
  </joint>

  
  <!-- Body motor -->
  <link
    name="body">
    <inertial>
      <origin
        xyz="-0.0881112438415369 -0.000608832310704913 0.590311564445662"
        rpy="0 0 0" />
      <mass
        value="1" />
      <inertia
        ixx="0.002"  ixy="0.000"  ixz="0.000"
        iyy="0.002"  iyz="0.000"
        izz="0.002" />
    </inertial>
    
    <visual>
      <origin
        xyz="0 0 0"
        rpy="0 0 0" />
      <geometry>
        <mesh
          filename="package://golem_description/meshes/body.STL" />
      </geometry>
      <material
        name="">
        <color
          rgba="1.0 0.9 0.8 1" />
      </material>
    </visual>
    
    <collision>
      <origin
        xyz="0 0 0"
        rpy="0 0 0" />
      <geometry>
        <mesh
          filename="package://golem_description/meshes/body.STL" />
      </geometry>
    </collision>
  </link>
  
  <joint
    name="mb"
    type="prismatic">
    <origin
      xyz="0.12661 -0.005 0.37"
      rpy="0.0 0.0 0.0" />
    <parent
      link="base_link" />
    <child
      link="body" />
    <axis
      xyz="0 0 1" />
    <limit
      lower="0.0"
      upper="0.55"
      effort="5000.0"
      velocity="0.005" />
    <dynamics 
      friction="${FRICTION}"/>
  </joint>
  

  <!-- Chest motor -->
  <link
    name="chest">
    <inertial>
      <origin
        xyz="-0.00897011879110521 0.0 0.0676449232079905"
        rpy="0 0 0" />
      <mass
        value="1.5" />
      <inertia
        ixx="0.0020"  ixy="0.0000"   ixz="0.0000"
        iyy="0.0020"  iyz="0.0"
        izz="0.0020" />
    </inertial>
    
    <visual>
      <origin
        xyz="0 0 0"
        rpy="0 0 0" />
      <geometry>
        <mesh
          filename="package://golem_description/meshes/chest.STL" />
      </geometry>
      <material
        name="">
        <color
          rgba="0.5 0.5 0.5 1" />
      </material>
    </visual>
    
    <collision>
      <origin
        xyz="0 0 0"
        rpy="0 0 0" />
      <geometry>
        <mesh
          filename="package://golem_description/meshes/chest.STL" />
      </geometry>
    </collision>
  </link>
  
  <joint
    name="m0"
    type="revolute">
    <origin
      xyz="0.035 0.0 0.8586"
      rpy="0.0 0.0 0.0" />
    <parent
      link="body" />
    <child
      link="chest" />
    <axis
      xyz="0 0 1" />
    <limit
      lower="-1"
      upper="1"
      effort="8.4"
      velocity="${JOINT_VEL}" />
    <dynamics 
      friction="${FRICTION}"/>
  </joint>
  

  <!-- Head motor 1 -->
  <link
    name="head1">
    <inertial>
      <origin
        xyz="-0.000589635969266311 0.00186429345558344 0.0382546423491974"
        rpy="0 0 0" />
      <mass
        value="0.193219512017787" />
      <inertia
        ixx="0.0008"   ixy="0.0000"   ixz="0.0000"
        iyy="0.0008"   iyz="0.0000"
        izz="0.0008" />
    </inertial>

    <visual>
      <origin
        xyz="0 0 0"
        rpy="0 0 0" />
      <geometry>
        <mesh
          filename="package://golem_description/meshes/head1.STL" />
      </geometry>
      <material
        name="">
        <color
          rgba="0.8 0.8 1 1" />
      </material>
    </visual>
    
    <collision>
      <origin
        xyz="0 0 0"
        rpy="0 0 0" />
      <geometry>
        <mesh
          filename="package://golem_description/meshes/head1.STL" />
      </geometry>
    </collision>
  </link>
  
  <joint
    name="m1"
    type="revolute">
    <origin
      xyz="-0.028554 0.0 0.1328"
      rpy="0.0 0.0 0.0" />
    <parent
      link="chest" />
    <child
      link="head1" />
    <axis
      xyz="0 0 1" />
    <limit
      lower="-1"
      upper="1"
      effort="8.4"
      velocity="${JOINT_VEL}" />
    <dynamics 
      friction="${FRICTION}"/>
  </joint>
  

  <!--Head motor 2 -->
  <link
    name="head2">
    <inertial>
      <origin
        xyz="-0.00618689637113473 0.0318619756298293 0.0631104669015432"
        rpy="0 0 0" />
      <mass
        value="1.89645146647976" />
      <inertia
        ixx="0.00655280092224716"
        ixy="-0.000266070117443091"
        ixz="5.61027113118384E-05"
        iyy="0.00607332840627649"
        iyz="0.000107578929571448"
        izz="0.0106713644751898" />
    </inertial>
    
    <visual>
      <origin
        xyz="0 0 0"
        rpy="0 0 0" />
      <geometry>
        <mesh
          filename="package://golem_description/meshes/head2.STL" />
      </geometry>
      <material
        name="">
        <color
          rgba="0 0.752941176470588 0.752941176470588 1" />
      </material>
    </visual>
    
    <collision>
      <origin
        xyz="0 0 0"
        rpy="0 0 0" />
      <geometry>
        <mesh
          filename="package://golem_description/meshes/head2.STL" />
      </geometry>
    </collision>
  </link>
  
  <joint
    name="m2"
    type="revolute">
    <origin
      xyz="0.050318 0.064987 0.12937"
      rpy="1.5708 0.0 0.0" />
    <parent
      link="head1" />
    <child
      link="head2" />
    <axis
      xyz="0 0 1" />
    <limit
      lower="-1"
      upper="1"
      effort="8.4"
      velocity="${JOINT_VEL}" />
    <dynamics 
      friction="${FRICTION}"/>
  </joint>



  <!--Right shoulder m10 motor -->
  <link
    name="r_shoulder_m10">
    <inertial>
      <origin
        xyz="0.117811024350009 -2.32352220330134E-05 0.0429372756020914"
        rpy="0 0 0" />
      <mass
        value="0.5" />
      <inertia
        ixx="0.0020"  ixy="0.0000"   ixz="0.0000"
        iyy="0.0020"  iyz="0.0000"
        izz="0.0020" />
    </inertial>
    
    <visual>
      <origin
        xyz="0 0 0"
        rpy="0 0 0" />
      <geometry>
        <mesh
          filename="package://golem_description/meshes/r_shoulder_m10.STL" />
      </geometry>
      <material
        name="">
        <color
          rgba="1 0.5 0.5 1" />
      </material>
    </visual>
    
    <collision>
      <origin
        xyz="0 0 0"
        rpy="0 0 0" />
      <geometry>
        <mesh
          filename="package://golem_description/meshes/r_shoulder_m10.STL" />
      </geometry>
    </collision>
  </link>
  
  <joint
    name="m10"
    type="revolute">
    <origin
      xyz="0 -0.1225 0.059"
      rpy="0.0 0.0 -1.5708" />
    <parent
      link="chest" />
    <child
      link="r_shoulder_m10" />
    <axis
      xyz="0 0 1" />
    <limit
      lower="-1.14"
      upper="1.75"
      effort="100.0"
      velocity="${JOINT_VEL}" />
    <dynamics 
      friction="${FRICTION}"/>
  </joint>



  <!--Right shoulder m11 motor -->
  <link
    name="r_shoulder_m11">
    <inertial>
      <origin
        xyz="-0.00429117580061061 0.0 -0.0397852819427538"
        rpy="0 0 0" />
      <mass
        value="0.009" />
      <inertia
        ixx="0.0002"     ixy="0.0"   ixz="0.0"
        iyy="0.0002"     iyz="0.0"
        izz="0.0002"/>
    </inertial>
    
    <visual>
      <origin
        xyz="0 0 0"
        rpy="0 0 0" />
      <geometry>
        <mesh
          filename="package://golem_description/meshes/r_shoulder_m11.STL" />
      </geometry>
      <material
        name="">
        <color
          rgba="0.5 0.5 0.5 1" />
      </material>
    </visual>
    
    <collision>
      <origin
        xyz="0 0 0"
        rpy="0 0 0" />
      <geometry>
        <mesh
          filename="package://golem_description/meshes/r_shoulder_m11.STL" />
      </geometry>
    </collision>
  </link>


  
  <joint
    name="m11"
    type="revolute">
    <origin
      xyz="0.212 0.0 0.0554"
      rpy="0.0 0.0 0.0" />
    <parent
      link="r_shoulder_m10" />
    <child
      link="r_shoulder_m11" />
    <axis
      xyz="0 0 1" />
    <limit
      lower="-3"
      upper="3"
      effort="100.0"
      velocity="${JOINT_VEL}" />
    <dynamics 
      friction="${FRICTION}"/>
  </joint>
  

  <!-- Right arm motor -->
  <link
    name="r_arm">
    <inertial>
      <origin
        xyz="0.131360969349986 0.00869049182380488 0.000487078032783306"
        rpy="0 0 0" />
      <mass
        value="0.5" />
      <inertia
        ixx="0.002"  ixy="0.0000"  ixz="0.0000"
        iyy="0.002"  iyz="0.0000"
        izz="0.002" />
    </inertial>
    
    <visual>
      <origin
        xyz="0 0 0"
        rpy="0 0 0" />
      <geometry>
        <mesh
          filename="package://golem_description/meshes/r_arm.STL" />
      </geometry>
      <material
        name="">
        <color
          rgba="0.501960784313725 1 0.501960784313725 1" />
      </material>
    </visual>
    
    <collision>
      <origin
        xyz="0 0 0"
        rpy="0 0 0" />
      <geometry>
        <mesh
          filename="package://golem_description/meshes/r_arm.STL" />
      </geometry>
    </collision>
  </link>
  
  <joint
    name="m12"
    type="revolute">
    <origin
      xyz="0.0 0.0 -0.06"
      rpy="0.0 ${PI/2} 0" />
    <parent
      link="r_shoulder_m11" />
    <child
      link="r_arm" />
    <axis
      xyz="0 0 1" />
    <limit
      lower="-1.55"
      upper="1.55"
      effort="100.0"
      velocity="${JOINT_VEL}" />
    <dynamics 
      friction="${FRICTION}"/>
  </joint>
  

  <!-- Right forearm  -->
  <link
    name="r_forearm">
    <inertial>
      <origin
        xyz="0.108270232216097 0.0483698597482063 -0.000350351491485268"
        rpy="0 0 0" />
      <mass
        value="1.0" />
      <inertia
        ixx="0.001"  ixy="0.0000"  ixz="0.0000"
        iyy="0.001"  iyz="0.0000"
        izz="0.002" />
    </inertial>
    
    <visual>
      <origin
        xyz="0 0 0"
        rpy="0 0 ${-PI/4}" />
      <geometry>
        <mesh
          filename="package://golem_description/meshes/r_forearm.STL" />
      </geometry>
      <material
        name="">
        <color
          rgba="0.501960784313725 0.501960784313725 1 1" />
      </material>
    </visual>
    
    <collision>
      <origin
        xyz="0 0 0"
        rpy="0 0 ${-PI/4}" />
      <geometry>
        <mesh
          filename="package://golem_description/meshes/r_forearm.STL" />
      </geometry>
    </collision>
  </link>
  
  <joint
    name="m13"
    type="revolute">
    <origin
      xyz="0.249 0.060 0"
      rpy="0.0 0.0 ${PI/2}" />
    <parent
      link="r_arm" />
    <child
      link="r_forearm" />
    <axis
      xyz="0 0 1" />
    <limit
      lower="-1.67"
      upper="1.67"
      effort="100.0"
      velocity="${JOINT_VEL}" />
    <dynamics 
      friction="${FRICTION}"/>
  </joint>


  <!-- Right wrist motor -->
  <link
    name="r_wrist">
    <inertial>
      <origin
        xyz="0.0049946466652247 -0.00176382149218224 0.0531597075092114"
        rpy="0 0 0" />
      <mass
        value="0.031134878193257" />
      <inertia
        ixx="0.00003"   ixy="0.0000"    ixz="0.0000"
        iyy="0.00005"   iyz="0.0000"
        izz="0.00003" />
    </inertial>
    
    <visual>
      <origin
        xyz="0 0 0"
        rpy="0 0 0" />
      <geometry>
        <mesh
          filename="package://golem_description/meshes/r_wrist.STL" />
      </geometry>
      <material
        name="">
        <color
          rgba="1 0.501960784313725 1 1" />
      </material>
    </visual>
    
    <collision>
      <origin
        xyz="0 0 0"
        rpy="0 0 0" />
      <geometry>
        <mesh
          filename="package://golem_description/meshes/r_wrist.STL" />
      </geometry>
    </collision>
  </link>
  
  <!--"0.16536 0.11838 0.0"-->
  <joint
    name="m14"
    type="revolute">
    <origin
      xyz= "0.200 -0.034 0"
      rpy="${PI/2} 0.0 ${PI/2}" />
    <parent
      link="r_forearm" />
    <child
      link="r_wrist" />
    <axis
      xyz="0 0 1" />
    <limit
      lower="-1.5"
      upper="1.5"
      effort="100.0"
      velocity="${JOINT_VEL}" />
    <dynamics 
      friction="${FRICTION}"/>
  </joint>


  <!-- Right virtual joint to indicate center of the gripper -->
  <link
    name="r_eef" />

  <joint
    name="r_eef_end"
    type="fixed">
    <origin
      xyz="0.0 0.0 0.2"
      rpy="${-PI/2} ${-PI/2} ${-PI/2}" />
    <parent
      link="r_wrist" />
    <child
      link="r_eef" />
  </joint>


  <!-- Right gripper m15 motor -->
  <link
    name="r_gripper_m15">
    <inertial>
      <origin
        xyz="0.0668949493902101 -0.00886945271498024 0.00431771664598063"
        rpy="0 0 0" />
      <mass
        value="0.0609094064539815" />
      <inertia
        ixx="0.00020"   ixy="0.0000"    ixz="0.0000"
        iyy="0.00020"   iyz="0.0000"    
        izz="0.00020" />
    </inertial>
    
    <visual>
      <origin
        xyz="0 0 0"
        rpy="0 0 0" />
      <geometry>
        <mesh
          filename="package://golem_description/meshes/r_gripper_m15.STL" />
      </geometry>
      <material
        name="">
        <color
          rgba="0.792156862745098 0.819607843137255 0.933333333333333 1" />
      </material>
    </visual>
    
    <collision>
      <origin
        xyz="0 0 0"
        rpy="0 0 0" />
      <geometry>
        <mesh
          filename="package://golem_description/meshes/r_gripper_m15.STL" />
      </geometry>
    </collision>
  </link>
  
  <joint
    name="m15"
    type="revolute">
    <origin
      xyz="0.0 0.010755 0.10471"
      rpy="${-PI/2} ${-PI/2} ${-PI/2}" />
    <parent
      link="r_wrist" />
    <child
      link="r_gripper_m15" />
    <axis
      xyz="0 0 -1" />
    <limit
      lower="0"
      upper="1.6"
      effort="1.5"
      velocity="${JOINT_VEL}" />
    <dynamics 
      friction="${FRICTION}"/>
  </joint>

 
  <!-- Right gripper m17 motor-->
  <link
    name="r_gripper_m17">
    <inertial>
      <origin
        xyz="0.06689494939021 0.00886945271498008 0.00431771664598052"
        rpy="0 0 0" />
      <mass
        value="0.0609094064539814" />
      <inertia
        ixx="0.00020"   ixy="0.0000"    ixz="0.0000"
        iyy="0.00020"   iyz="0.0000"    
        izz="0.00020" />
    </inertial>
    
    <visual>
      <origin
        xyz="0 0 0"
        rpy="0 0 0" />
      <geometry>
        <mesh
          filename="package://golem_description/meshes/r_gripper_m17.STL" />
      </geometry>
      <material
        name="">
        <color
          rgba="0.792156862745098 0.819607843137255 0.933333333333333 1" />
      </material>
    </visual>
    
    <collision>
      <origin
        xyz="0 0 0"
        rpy="0 0 0" />
      <geometry>
        <mesh
          filename="package://golem_description/meshes/r_gripper_m17.STL" />
      </geometry>
    </collision>
  </link>
  
  <joint
    name="m17"
    type="revolute">
    <origin
      xyz="0.0003 -0.021173 0.10255"
      rpy="${-PI/2} 0.0 ${-PI/2}" />
    <parent
      link="r_wrist" />
    <child
      link="r_gripper_m17" />
    <axis
      xyz="0 0 -1" />
    <limit
      lower="0"
      upper="1.6"
      effort="1.5"
      velocity="${JOINT_VEL}" />
    <dynamics 
      friction="${FRICTION}"/>
  </joint>
  

  <!-- Left shouder m20 motor -->
  <link
    name="l_shoulder_m20">
    <inertial>
      <origin
        xyz="0.117811024349998 -2.32352220331244E-05 0.0429372756020854"
        rpy="0 0 0" />
      <mass
        value="0.5" />
      <inertia
        ixx="0.002"  ixy="0.0000"   ixz="0.000"
        iyy="0.002"  iyz="0.0000"
        izz="0.002" />
    </inertial>
    
    <visual>
      <origin
        xyz="0 0 0"
        rpy="0 0 0" />
      <geometry>
        <mesh
          filename="package://golem_description/meshes/l_shoulder_m20.STL" />
      </geometry>
      <material
        name="">
        <color
          rgba="1 0.501960784313725 0.501960784313725 1" />
      </material>
    </visual>
    
    <collision>
      <origin
        xyz="0 0 0"
        rpy="0 0 0" />
      <geometry>
        <mesh
          filename="package://golem_description/meshes/l_shoulder_m20.STL" />
      </geometry>
    </collision>
  </link>
  
  <joint
    name="m20"
    type="revolute">
    <origin
      xyz="0 0.1225 0.0593" 
      rpy="0.0 0.0 1.5708" />
    <parent
      link="chest" />
    <child
      link="l_shoulder_m20" />
    <axis
      xyz="0 0 1" />
    <limit
      lower="-1.14"
      upper="1.75"
      effort="100"
      velocity="${JOINT_VEL}" />
    <dynamics 
      friction="${FRICTION}"/>
  </joint>


  <!-- Left shoulder m21 motor-->
  <link
    name="l_shoulder_m21">
    <inertial>
      <origin
        xyz="0.00429943368445523 -4.92661467177413E-13 0.0397852819427535"
        rpy="0 0 0" />
      <mass
        value="0.009" />
      <inertia
        ixx="0.0002"     ixy="0.0"   ixz="0.0"
        iyy="0.0002"     iyz="0.0"
        izz="0.0002"/>
    </inertial>
    
    <visual>
      <origin
        xyz="0 0 0"
        rpy="0 0 0" />
      <geometry>
        <mesh
          filename="package://golem_description/meshes/l_shoulder_m21.STL" />
      </geometry>
      <material
        name="">
        <color
          rgba="0.501960784313725 0.501960784313725 0.501960784313725 1" />
      </material>
    </visual>
    
    <collision>
      <origin
        xyz="0 0 0"
        rpy="0 0 0" />
      <geometry>
        <mesh
          filename="package://golem_description/meshes/l_shoulder_m21.STL" />
      </geometry>
    </collision>
  </link>
  
  <joint
    name="m21"
    type="revolute">
    <origin
      xyz="0.212 0.0 0.054396"
      rpy="-3.1416 0.0 3.1416" />
    <parent
      link="l_shoulder_m20" />
    <child
      link="l_shoulder_m21" />
    <axis
      xyz="0 0 1" />
    <limit
      lower="-3"
      upper="3"
      effort="100"
      velocity="${JOINT_VEL}" />
    <dynamics 
      friction="${FRICTION}"/>
  </joint>
  

  <!-- Left arm motor -->
  <link
    name="l_arm">
    <inertial>
      <origin
        xyz="0.131360969349986 0.00869049182380505 0.00048707803278325"
        rpy="0 0 0" />
      <mass
        value="0.5" />
      <inertia
        ixx="0.002"  ixy="0.0000"  ixz="0.0000"
        iyy="0.002"  iyz="0.0000"
        izz="0.002" />
    </inertial>
    
    <visual>
      <origin
        xyz="0 0 0"
        rpy="0 0 0" />
      <geometry>
        <mesh
          filename="package://golem_description/meshes/l_arm.STL" />
      </geometry>
      <material
        name="">
        <color
          rgba="0.501960784313725 1 0.501960784313725 1" />
      </material>
    </visual>
    
    <collision>
      <origin
        xyz="0 0 0"
        rpy="0 0 0" />
      <geometry>
        <mesh
          filename="package://golem_description/meshes/l_arm.STL" />
      </geometry>
    </collision>
  </link>
  
  <joint
    name="m22"
    type="revolute">
    <origin
      xyz="0.0 0.0 0.06"
      rpy="${PI} ${-PI/2} 0.0" />
    <parent
      link="l_shoulder_m21" />
    <child
      link="l_arm" />
    <axis
      xyz="0 0 -1" />
    <limit
      lower="-1.55"
      upper="1.55"
      effort="100.0"
      velocity="${JOINT_VEL}" />
    <dynamics 
      friction="${FRICTION}"/>
  </joint>


  <!-- Left Forearm motor -->
  <link
    name="l_forearm">
    <inertial>
      <origin
        xyz="0.108270232216093 0.0483698597482032 -0.000350351491486045"
        rpy="0 0 0" />
      <mass
        value="1.0" />
      <inertia
        ixx="0.002"  ixy="0.0000"  ixz="0.0000"
        iyy="0.002"  iyz="0.0000"
        izz="0.002" />
    </inertial>
    
    <visual>
      <origin
        xyz="0 0 0"
        rpy="0 0 ${-PI/4}" />
      <geometry>
        <mesh
          filename="package://golem_description/meshes/l_forearm.STL" />
      </geometry>
      <material
        name="">
        <color
          rgba="0.501960784313725 0.501960784313725 1 1" />
      </material>
    </visual>
    
    <collision>
      <origin
        xyz="0 0 0"
        rpy="0 0 ${-PI/4}" />
      <geometry>
        <mesh
          filename="package://golem_description/meshes/l_forearm.STL" />
      </geometry>
    </collision>
  </link>

  <joint
    name="m23"
    type="revolute">
    <origin
      xyz="0.24895 0.05978 0.0"
      rpy="0.0 0.0 ${PI/2}" />
    <parent
      link="l_arm" />
    <child
      link="l_forearm" />
    <axis
      xyz="0 0 -1" />
    <limit
      lower="-1.55"
      upper="1.55"
      effort="100.0"
      velocity="${JOINT_VEL}" />
    <dynamics 
      friction="${FRICTION}"/>
  </joint>


  <!-- Left wrist motor -->
  <link
    name="l_wrist">
    <inertial>
      <origin
        xyz="0.00499371660552256 -0.00176269973546561 0.0531563838624657"
        rpy="0 0 0" />
      <mass
        value="0.03" />
      <inertia
        ixx="0.00003"   ixy="0.0000"    ixz="0.0000"
        iyy="0.00003"   iyz="0.0000"
        izz="0.00003" />
    </inertial>
    
    <visual>
      <origin
        xyz="0.0 0.0 0.0"
        rpy="0.0 0.0 0.0" />
      <geometry>
        <mesh
          filename="package://golem_description/meshes/l_wrist.STL" />
      </geometry>
      <material
        name="">
        <color
          rgba="1 0.501960784313725 1 1" />
      </material>
    </visual>
    
    <collision>
      <origin
        xyz="0.0 0.0 0.0"
        rpy="0.0 0.0 0.0" />
      <geometry>
        <mesh
          filename="package://golem_description/meshes/l_wrist.STL" />
      </geometry>
    </collision>
  </link>

  <joint
    name="m24"
    type="revolute">
    <origin
      xyz="0.2 -0.034 0.0"
      rpy="${PI/2} 0.0 ${PI/2}" />
    <parent
      link="l_forearm" />
    <child
      link="l_wrist" />
    <axis
      xyz="0 0 1" />
    <limit
      lower="-1.67"
      upper="1.67"
      effort="3.7"
      velocity="${JOINT_VEL}" />
    <dynamics 
      friction="${FRICTION}"/>
  </joint>


  <!-- Left virtual joint to indicate center of the gripper -->
  <link name="l_eef" />

  <joint
    name="l_eef_end"
    type="fixed">
    <origin
      xyz="0.0 0.0 0.2"
      rpy="${-PI/2} ${-PI/2} ${-PI/2}" />
    <parent
      link="l_wrist" />
    <child
      link="l_eef" />
  </joint>


  <!-- Ledt gripper m25 motor -->
  <link
    name="l_gripper_m25">
    <inertial>
      <origin
        xyz="0.0668949493902099 -0.00886945271498052 0.00431771664598046"
        rpy="0 0 0" />
      <mass
        value="0.0609094064539814" />
      <inertia
        ixx="0.00004"   ixy="0.0000"    ixz="0.0000"
        iyy="0.00020"   iyz="0.0000"    
        izz="0.00020" />
    </inertial>
    
    <visual>
      <origin
        xyz="0 0 0"
        rpy="0 0 0" />
      <geometry>
        <mesh
          filename="package://golem_description/meshes/l_gripper_m25.STL" />
      </geometry>
      <material
        name="">
        <color
          rgba="0.792156862745098 0.819607843137255 0.933333333333333 1" />
      </material>
    </visual>
    
    <collision>
      <origin
        xyz="0 0 0"
        rpy="0 0 0" />
      <geometry>
        <mesh
          filename="package://golem_description/meshes/l_gripper_m25.STL" />
      </geometry>
    </collision>
  </link>
  
  <joint
    name="m25"
    type="revolute">
    <origin
      xyz="0.0 0.010755 0.10471"
      rpy="${-PI/2} ${-PI/2} ${-PI/2}" />
    <parent
      link="l_wrist" />
    <child
      link="l_gripper_m25" />
    <axis
      xyz="0 0 -1" />
    <limit
      lower="0"
      upper="1.6"
      effort="100.0"
      velocity="${JOINT_VEL}" />
    <dynamics 
      friction="${FRICTION}"/>
  </joint>


  <!-- Left gripper m27 motor -->
  <link
    name="l_gripper_m27">
    <inertial>
      <origin
        xyz="0.0668949493902098 0.00886945271498041 0.00431771664598063"
        rpy="0 0 0" />
      <mass
        value="0.0609094064539813" />
      <inertia
        ixx="0.0002"   ixy="0.0000"    ixz="0.0000"
        iyy="0.0002"   iyz="0.0000"    
        izz="0.0002" />
    </inertial>
    
    <visual>
      <origin
        xyz="0 0 0"
        rpy="0 0 0" />
      <geometry>
        <mesh
          filename="package://golem_description/meshes/l_gripper_m27.STL" />
      </geometry>
      <material
        name="">
        <color
          rgba="0.792156862745098 0.819607843137255 0.933333333333333 1" />
      </material>
    </visual>
    
    <collision>
      <origin
        xyz="0 0 0"
        rpy="0 0 0" />
      <geometry>
        <mesh
          filename="package://golem_description/meshes/l_gripper_m27.STL" />
      </geometry>
    </collision>
  </link>
  
  <joint
    name="m27"
    type="revolute">
    <origin
      xyz="0.003 -0.021173 0.10255"
      rpy="${-PI/2} 0.0 ${-PI/2}" />
    <parent
      link="l_wrist" />
    <child
      link="l_gripper_m27" />
    <axis
      xyz="0 0 -1" />
    <limit
      lower="0"
      upper="1.6"
      effort="100.0"
      velocity="${JOINT_VEL}" />
    <dynamics 
      friction="${FRICTION}"/>
  </joint>


  <!-- Transmission elements-->
  <!-- Necessary for the ros_control simulation -->

  <!--Body-->
  <transmission   name="body_transmission">
    <type>transmission_interface/SimpleTransmission</type>
    <joint  name="mb">
      <hardwareInterface>${CONTROLLER}</hardwareInterface>
    </joint>

    <actuator   name="body_motor">
      <mechanicalReduction>1</mechanicalReduction>
    </actuator>
  </transmission>


  <!--Chest-->
  <transmission   name="chest_transmission">
    <type>transmission_interface/SimpleTransmission</type>
    <joint  name="m0">
      <hardwareInterface>${CONTROLLER}</hardwareInterface>
    </joint>

    <actuator   name="chest_motor">
      <mechanicalReduction>1</mechanicalReduction>
    </actuator>
  </transmission>


  <!--Head 1-->
  <transmission   name="head1_transmission">
    <type>transmission_interface/SimpleTransmission</type>
    <joint  name="m1">
      <hardwareInterface>${CONTROLLER}</hardwareInterface>
    </joint>
    
    <actuator   name="head1_motor">
      <mechanicalReduction>2</mechanicalReduction>
    </actuator>
  </transmission>


  <!-- Head 2 -->
  <transmission   name="head2_transmission">
    <type>transmission_interface/SimpleTransmission</type>
    <joint  name="m2">
      <hardwareInterface>${CONTROLLER}</hardwareInterface>
    </joint>

    <actuator   name="head2_motor">
      <mechanicalReduction>0.5</mechanicalReduction>
    </actuator>
  </transmission>


  <!-- Right shoulder motor 10 -->
  <transmission 
    name="r_shoulder10_transmission">
    <type>transmission_interface/SimpleTransmission</type>
    <joint  name="m10">
      <hardwareInterface>${CONTROLLER}</hardwareInterface>
    </joint>

    <actuator   name="r_shoulder10_motor">
      <mechanicalReduction>1</mechanicalReduction>
    </actuator>
  </transmission>


  <!-- Right shoulder motor 11 -->
  <transmission   name="r_shoulder11_transmission">
    <type>transmission_interface/SimpleTransmission</type>
    <joint  name="m11">
      <hardwareInterface>${CONTROLLER}</hardwareInterface>
    </joint>

    <actuator   name="r_shoulder11_motor">
      <mechanicalReduction>1</mechanicalReduction>
    </actuator>
  </transmission>


  <!-- Right arm -->
  <transmission   name="r_arm_transmission">
    <type>transmission_interface/SimpleTransmission</type>
    <joint  name="m12">
      <hardwareInterface>${CONTROLLER}</hardwareInterface>
    </joint>

    <actuator   name="r_arm_motor">
      <mechanicalReduction>1</mechanicalReduction>
    </actuator>
  </transmission>


  <!-- Right forearm -->
  <transmission   name="r_forearm_transmission">
    <type>transmission_interface/SimpleTransmission</type>
    <joint  name="m13">
      <hardwareInterface>${CONTROLLER}</hardwareInterface>
    </joint>

    <actuator   name="r_forearm_motor">
      <mechanicalReduction>1</mechanicalReduction>
    </actuator>
  </transmission>


  <!-- Right wrist -->
  <transmission   name="r_wrist_transmission">
    <type>transmission_interface/SimpleTransmission</type>
    <joint  name="m14">
      <hardwareInterface>${CONTROLLER}</hardwareInterface>
    </joint>

    <actuator   name="r_wrist_motor">
      <mechanicalReduction>1</mechanicalReduction>
    </actuator>
  </transmission>


  <!-- Right gripper motor 15 -->
  <transmission   name="r_gripper15_transmission">
    <type>transmission_interface/SimpleTransmission</type>
    <joint  name="m15">
      <hardwareInterface>${CONTROLLER}</hardwareInterface>
    </joint>

    <actuator   name="r_gripper15_motor">
      <mechanicalReduction>1</mechanicalReduction>
    </actuator>
  </transmission>


  <!-- Right gripper motor 17 -->
  <transmission   name="r_gripper17_transmission">
    <type>transmission_interface/SimpleTransmission</type>
    <joint  name="m17">
      <hardwareInterface>${CONTROLLER}</hardwareInterface>
    </joint>

    <actuator   name="r_gripper17_motor">
      <mechanicalReduction>1</mechanicalReduction>
    </actuator>
  </transmission>

  <!-- Left shoulder motor 20 -->
  <transmission 
    name="l_shoulder20_transmission">
    <type>transmission_interface/SimpleTransmission</type>
    <joint  name="m20">
      <hardwareInterface>${CONTROLLER}</hardwareInterface>
    </joint>

    <actuator   name="r_shoulder20_motor">
      <mechanicalReduction>1</mechanicalReduction>
    </actuator>
  </transmission>


  <!-- Left shoulder motor 21 -->
  <transmission   name="l_shoulder21_transmission">
    <type>transmission_interface/SimpleTransmission</type>
    <joint  name="m21">
      <hardwareInterface>${CONTROLLER}</hardwareInterface>
    </joint>

    <actuator   name="l_shoulder21_motor">
      <mechanicalReduction>1</mechanicalReduction>
    </actuator>
  </transmission>


  <!-- Left arm -->
  <transmission   name="l_arm_transmission">
    <type>transmission_interface/SimpleTransmission</type>
    <joint  name="m22">
      <hardwareInterface>${CONTROLLER}</hardwareInterface>
    </joint>

    <actuator   name="l_arm_motor">
      <mechanicalReduction>1</mechanicalReduction>
    </actuator>
  </transmission>


  <!-- Left forearm -->
  <transmission   name="l_forearm_transmission">
    <type>transmission_interface/SimpleTransmission</type>
    <joint  name="m23">
      <hardwareInterface>${CONTROLLER}</hardwareInterface>
    </joint>

    <actuator   name="l_forearm_motor">
      <mechanicalReduction>1</mechanicalReduction>
    </actuator>
  </transmission>


  <!-- Left wrist -->
  <transmission   name="l_wrist_transmission">
    <type>transmission_interface/SimpleTransmission</type>
    <joint  name="m24">
      <hardwareInterface>${CONTROLLER}</hardwareInterface>
    </joint>

    <actuator   name="l_wrist_motor">
      <mechanicalReduction>1</mechanicalReduction>
    </actuator>
  </transmission>


  <!-- Left gripper motor 25 -->
  <transmission   name="l_gripper25_transmission">
    <type>transmission_interface/SimpleTransmission</type>
    <joint  name="m25">
      <hardwareInterface>${CONTROLLER}</hardwareInterface>
    </joint>

    <actuator   name="l_gripper25_motor">
      <mechanicalReduction>1</mechanicalReduction>
    </actuator>
  </transmission>


  <!-- Left gripper motor 27 -->
  <transmission   name="l_gripper27_transmission">
    <type>transmission_interface/SimpleTransmission</type>
    <joint  name="m27">
      <hardwareInterface>${CONTROLLER}</hardwareInterface>
    </joint>

    <actuator   name="l_gripper27_motor">
      <mechanicalReduction>1</mechanicalReduction>
    </actuator>
  </transmission>



</robot>