<?xml version="1.0" ?>
<!-- =================================================================================== -->
<!-- |    This document was autogenerated by xacro from golem.xacro                    | -->
<!-- |    EDITING THIS FILE BY HAND IS NOT RECOMMENDED                                 | -->
<!-- =================================================================================== -->
<!-- 
Author: Uriel Ortiz   
E-Mail: euriel.ortiz@gmail.com    
Date:   august/2016

This is the main XML code for the Golem URDF.
URDF allow to simulate accurately geometry and kinematics of a robot
with programs like gazebo or rviz.
-->
<robot name="golem">

  <!-- Used for fixing robot to Gazebo 'base_link' -->
  <link name="world"/>
  <!-- Base link -->
  <link name="base_link">
    <inertial>
      <origin rpy="0 0 0" xyz="0.0 0.0 0.0"/>
      <mass value="2"/>
      <inertia ixx="0.002" ixy="0.0000" ixz="0.0000" iyy="0.002" iyz="0.0000" izz="0.002"/>
    </inertial>
    <visual>
      <origin rpy="0 0 0" xyz="0 0 0"/>
      <geometry>
        <mesh filename="package://golem_description/meshes/base_link.STL"/>
      </geometry>
      <material name="">
        <color rgba="0.5 0.5 1 1"/>
      </material>
    </visual>
    <collision>
      <origin rpy="0 0 0" xyz="0 0 0"/>
      <geometry>
        <mesh filename="package://golem_description/meshes/base_link.STL"/>
      </geometry>
    </collision>
  </link>
  <joint name="fixed" type="fixed">
    <parent link="world"/>
    <child link="base_link"/>
  </joint>
  <!-- Body motor -->
  <link name="body">
    <inertial>
      <origin rpy="0 0 0" xyz="-0.0881112438415369 -0.000608832310704913 0.590311564445662"/>
      <mass value="1"/>
      <inertia ixx="0.002" ixy="0.000" ixz="0.000" iyy="0.002" iyz="0.000" izz="0.002"/>
    </inertial>
    <visual>
      <origin rpy="0 0 0" xyz="0 0 0"/>
      <geometry>
        <mesh filename="package://golem_description/meshes/body.STL"/>
      </geometry>
      <material name="">
        <color rgba="1.0 0.9 0.8 1"/>
      </material>
    </visual>
    <collision>
      <origin rpy="0 0 0" xyz="0 0 0"/>
      <geometry>
        <mesh filename="package://golem_description/meshes/body.STL"/>
      </geometry>
    </collision>
  </link>
  <joint name="mb" type="prismatic">
    <origin rpy="0.0 0.0 0.0" xyz="0.12661 0.0 0.37"/>
    <parent link="base_link"/>
    <child link="body"/>
    <axis xyz="0 0 1"/>
    <limit effort="5000.0" lower="0.0" upper="0.55" velocity="0.005"/>
    <dynamics friction="0.6"/>
  </joint>
  <!-- Chest motor -->
  <link name="chest">
    <inertial>
      <origin rpy="0 0 0" xyz="-0.00897011879110521 0.0 0.0676449232079905"/>
      <mass value="1.5"/>
      <inertia ixx="0.0020" ixy="0.0000" ixz="0.0000" iyy="0.0020" iyz="0.0" izz="0.0020"/>
    </inertial>
    <visual>
      <origin rpy="0 0 0" xyz="0 0 0"/>
      <geometry>
        <mesh filename="package://golem_description/meshes/chest.STL"/>
      </geometry>
      <material name="">
        <color rgba="0.5 0.5 0.5 1"/>
      </material>
    </visual>
    <collision>
      <origin rpy="0 0 0" xyz="0 0 0"/>
      <geometry>
        <mesh filename="package://golem_description/meshes/chest.STL"/>
      </geometry>
    </collision>
  </link>
  <joint name="m0" type="revolute">
    <origin rpy="0.0 0.0 0.0" xyz="0.035 0.0 0.85"/>
    <parent link="body"/>
    <child link="chest"/>
    <axis xyz="0 0 1"/>
    <limit effort="8.4" lower="-1" upper="1" velocity="0.1"/>
    <dynamics friction="0.6"/>
  </joint>
  <!-- Head motor 1 -->
  <link name="head1">
    <inertial>
      <origin rpy="0 0 0" xyz="-0.000589635969266311 0.00186429345558344 0.0382546423491974"/>
      <mass value="0.193219512017787"/>
      <inertia ixx="0.0008" ixy="0.0000" ixz="0.0000" iyy="0.0008" iyz="0.0000" izz="0.0008"/>
    </inertial>
    <visual>
      <origin rpy="0 0 0" xyz="0 0 0"/>
      <geometry>
        <mesh filename="package://golem_description/meshes/head1.STL"/>
      </geometry>
      <material name="">
        <color rgba="0.8 0.8 1 1"/>
      </material>
    </visual>
    <collision>
      <origin rpy="0 0 0" xyz="0 0 0"/>
      <geometry>
        <mesh filename="package://golem_description/meshes/head1.STL"/>
      </geometry>
    </collision>
  </link>
  <joint name="m1" type="revolute">
    <origin rpy="0.0 0.0 0.0" xyz="-0.028554 0.0 0.1328"/>
    <parent link="chest"/>
    <child link="head1"/>
    <axis xyz="0 0 1"/>
    <limit effort="8.4" lower="-1" upper="1" velocity="0.1"/>
    <dynamics friction="0.6"/>
  </joint>
  <!--Head motor 2 -->
  <link name="head2">
    <inertial>
      <origin rpy="0 0 0" xyz="-0.00618689637113473 0.0318619756298293 0.0631104669015432"/>
      <mass value="1.89645146647976"/>
      <inertia ixx="0.00655280092224716" ixy="-0.000266070117443091" ixz="5.61027113118384E-05" iyy="0.00607332840627649" iyz="0.000107578929571448" izz="0.0106713644751898"/>
    </inertial>
    <visual>
      <origin rpy="0 0 0" xyz="0 0 0"/>
      <geometry>
        <mesh filename="package://golem_description/meshes/head2.STL"/>
      </geometry>
      <material name="">
        <color rgba="0 0.752941176470588 0.752941176470588 1"/>
      </material>
    </visual>
    <collision>
      <origin rpy="0 0 0" xyz="0 0 0"/>
      <geometry>
        <mesh filename="package://golem_description/meshes/head2.STL"/>
      </geometry>
    </collision>
  </link>
  <joint name="m2" type="revolute">
    <origin rpy="1.5708 0.0 0.0" xyz="0.050318 0.064987 0.12937"/>
    <parent link="head1"/>
    <child link="head2"/>
    <axis xyz="0 0 1"/>
    <limit effort="8.4" lower="-1" upper="1" velocity="0.1"/>
    <dynamics friction="0.6"/>
  </joint>
  <!--Right shoulder m10 motor -->
  <link name="r_shoulder_m10">
    <inertial>
      <origin rpy="0 0 0" xyz="0.117811024350009 -2.32352220330134E-05 0.0429372756020914"/>
      <mass value="0.5"/>
      <inertia ixx="0.0020" ixy="0.0000" ixz="0.0000" iyy="0.0020" iyz="0.0000" izz="0.0020"/>
    </inertial>
    <visual>
      <origin rpy="0 0 0" xyz="0 0 0"/>
      <geometry>
        <mesh filename="package://golem_description/meshes/r_shoulder_m10.STL"/>
      </geometry>
      <material name="">
        <color rgba="1 0.5 0.5 1"/>
      </material>
    </visual>
    <collision>
      <origin rpy="0 0 0" xyz="0 0 0"/>
      <geometry>
        <mesh filename="package://golem_description/meshes/r_shoulder_m10.STL"/>
      </geometry>
    </collision>
  </link>
  <joint name="m10" type="revolute">
    <origin rpy="0.0 0.0 -1.5708" xyz="0 -0.1225 0.0593"/>
    <parent link="chest"/>
    <child link="r_shoulder_m10"/>
    <axis xyz="0 0 1"/>
    <limit effort="100.0" lower="-1.14" upper="1.75" velocity="0.1"/>
    <dynamics friction="0.6"/>
  </joint>
  <!--Right shoulder m11 motor -->
  <link name="r_shoulder_m11">
    <inertial>
      <origin rpy="0 0 0" xyz="-0.00429117580061061 0.0 -0.0397852819427538"/>
      <mass value="0.009"/>
      <inertia ixx="0.0002" ixy="0.0" ixz="0.0" iyy="0.0002" iyz="0.0" izz="0.0002"/>
    </inertial>
    <visual>
      <origin rpy="0 0 0" xyz="0 0 0"/>
      <geometry>
        <mesh filename="package://golem_description/meshes/r_shoulder_m11.STL"/>
      </geometry>
      <material name="">
        <color rgba="0.5 0.5 0.5 1"/>
      </material>
    </visual>
    <collision>
      <origin rpy="0 0 0" xyz="0 0 0"/>
      <geometry>
        <mesh filename="package://golem_description/meshes/r_shoulder_m11.STL"/>
      </geometry>
    </collision>
  </link>
  <joint name="m11" type="revolute">
    <origin rpy="0.0 0.0 0.0" xyz="0.212 0.0 0.054396"/>
    <parent link="r_shoulder_m10"/>
    <child link="r_shoulder_m11"/>
    <axis xyz="0 0 1"/>
    <limit effort="100.0" lower="-3" upper="3" velocity="0.1"/>
    <dynamics friction="0.6"/>
  </joint>
  <!-- Right arm motor -->
  <link name="r_arm">
    <inertial>
      <origin rpy="0 0 0" xyz="0.131360969349986 0.00869049182380488 0.000487078032783306"/>
      <mass value="0.5"/>
      <inertia ixx="0.002" ixy="0.0000" ixz="0.0000" iyy="0.002" iyz="0.0000" izz="0.002"/>
    </inertial>
    <visual>
      <origin rpy="0 0 0" xyz="0 0 0"/>
      <geometry>
        <mesh filename="package://golem_description/meshes/r_arm.STL"/>
      </geometry>
      <material name="">
        <color rgba="0.501960784313725 1 0.501960784313725 1"/>
      </material>
    </visual>
    <collision>
      <origin rpy="0 0 0" xyz="0 0 0"/>
      <geometry>
        <mesh filename="package://golem_description/meshes/r_arm.STL"/>
      </geometry>
    </collision>
  </link>
  <joint name="m12" type="revolute">
    <origin rpy="0.0 1.57079632679 0" xyz="0.0 0.0 -0.06"/>
    <parent link="r_shoulder_m11"/>
    <child link="r_arm"/>
    <axis xyz="0 0 1"/>
    <limit effort="100.0" lower="-1.55" upper="1.55" velocity="0.1"/>
    <dynamics friction="0.6"/>
  </joint>
  <!-- Right forearm  -->
  <link name="r_forearm">
    <inertial>
      <origin rpy="0 0 0" xyz="0.108270232216097 0.0483698597482063 -0.000350351491485268"/>
      <mass value="1.0"/>
      <inertia ixx="0.001" ixy="0.0000" ixz="0.0000" iyy="0.001" iyz="0.0000" izz="0.002"/>
    </inertial>
    <visual>
      <origin rpy="0 0 -0.785398163397" xyz="0 0 0"/>
      <geometry>
        <mesh filename="package://golem_description/meshes/r_forearm.STL"/>
      </geometry>
      <material name="">
        <color rgba="0.501960784313725 0.501960784313725 1 1"/>
      </material>
    </visual>
    <collision>
      <origin rpy="0 0 -0.785398163397" xyz="0 0 0"/>
      <geometry>
        <mesh filename="package://golem_description/meshes/r_forearm.STL"/>
      </geometry>
    </collision>
  </link>
  <joint name="m13" type="revolute">
    <origin rpy="0.0 0.0 1.57079632679" xyz="0.24895 0.05978 0"/>
    <parent link="r_arm"/>
    <child link="r_forearm"/>
    <axis xyz="0 0 1"/>
    <limit effort="100.0" lower="-1.67" upper="1.67" velocity="0.1"/>
    <dynamics friction="0.6"/>
  </joint>
  <!-- Right wrist motor -->
  <link name="r_wrist">
    <inertial>
      <origin rpy="0 0 0" xyz="0.0049946466652247 -0.00176382149218224 0.0531597075092114"/>
      <mass value="0.031134878193257"/>
      <inertia ixx="0.00003" ixy="0.0000" ixz="0.0000" iyy="0.00005" iyz="0.0000" izz="0.00003"/>
    </inertial>
    <visual>
      <origin rpy="0 0 0" xyz="0 0 0"/>
      <geometry>
        <mesh filename="package://golem_description/meshes/r_wrist.STL"/>
      </geometry>
      <material name="">
        <color rgba="1 0.501960784313725 1 1"/>
      </material>
    </visual>
    <collision>
      <origin rpy="0 0 0" xyz="0 0 0"/>
      <geometry>
        <mesh filename="package://golem_description/meshes/r_wrist.STL"/>
      </geometry>
    </collision>
  </link>
  <!--"0.16536 0.11838 0.0"-->
  <joint name="m14" type="revolute">
    <origin rpy="1.57079632679 0.0 1.57079632679" xyz="0.200 -0.034 0"/>
    <parent link="r_forearm"/>
    <child link="r_wrist"/>
    <axis xyz="0 0 1"/>
    <limit effort="100.0" lower="-1.5" upper="1.5" velocity="0.1"/>
    <dynamics friction="0.6"/>
  </joint>
  <!-- Right virtual joint to indicate center of the gripper -->
  <link name="r_eef"/>
  <joint name="r_eef_end" type="fixed">
    <origin rpy="-1.57079632679 -1.57079632679 -1.57079632679" xyz="0.0 0.0 0.2"/>
    <parent link="r_wrist"/>
    <child link="r_eef"/>
  </joint>
  <!-- Right gripper m15 motor -->
  <link name="r_gripper_m15">
    <inertial>
      <origin rpy="0 0 0" xyz="0.0668949493902101 -0.00886945271498024 0.00431771664598063"/>
      <mass value="0.0609094064539815"/>
      <inertia ixx="0.00020" ixy="0.0000" ixz="0.0000" iyy="0.00020" iyz="0.0000" izz="0.00020"/>
    </inertial>
    <visual>
      <origin rpy="0 0 0" xyz="0 0 0"/>
      <geometry>
        <mesh filename="package://golem_description/meshes/r_gripper_m15.STL"/>
      </geometry>
      <material name="">
        <color rgba="0.792156862745098 0.819607843137255 0.933333333333333 1"/>
      </material>
    </visual>
    <collision>
      <origin rpy="0 0 0" xyz="0 0 0"/>
      <geometry>
        <mesh filename="package://golem_description/meshes/r_gripper_m15.STL"/>
      </geometry>
    </collision>
  </link>
  <joint name="m15" type="revolute">
    <origin rpy="-1.57079632679 -1.57079632679 -1.57079632679" xyz="0.0 0.010755 0.10471"/>
    <parent link="r_wrist"/>
    <child link="r_gripper_m15"/>
    <axis xyz="0 0 -1"/>
    <limit effort="1.5" lower="0" upper="1.6" velocity="0.1"/>
    <dynamics friction="0.6"/>
  </joint>
  <!-- Right gripper m17 motor-->
  <link name="r_gripper_m17">
    <inertial>
      <origin rpy="0 0 0" xyz="0.06689494939021 0.00886945271498008 0.00431771664598052"/>
      <mass value="0.0609094064539814"/>
      <inertia ixx="0.00020" ixy="0.0000" ixz="0.0000" iyy="0.00020" iyz="0.0000" izz="0.00020"/>
    </inertial>
    <visual>
      <origin rpy="0 0 0" xyz="0 0 0"/>
      <geometry>
        <mesh filename="package://golem_description/meshes/r_gripper_m17.STL"/>
      </geometry>
      <material name="">
        <color rgba="0.792156862745098 0.819607843137255 0.933333333333333 1"/>
      </material>
    </visual>
    <collision>
      <origin rpy="0 0 0" xyz="0 0 0"/>
      <geometry>
        <mesh filename="package://golem_description/meshes/r_gripper_m17.STL"/>
      </geometry>
    </collision>
  </link>
  <joint name="m17" type="revolute">
    <origin rpy="-1.57079632679 0.0 -1.57079632679" xyz="0.0003 -0.021173 0.10255"/>
    <parent link="r_wrist"/>
    <child link="r_gripper_m17"/>
    <axis xyz="0 0 -1"/>
    <limit effort="1.5" lower="0" upper="1.6" velocity="0.1"/>
    <dynamics friction="0.6"/>
  </joint>
  <!-- Left shouder m20 motor -->
  <link name="l_shoulder_m20">
    <inertial>
      <origin rpy="0 0 0" xyz="0.117811024349998 -2.32352220331244E-05 0.0429372756020854"/>
      <mass value="0.315227646337632"/>
      <inertia ixx="0.002" ixy="0.0000" ixz="0.000" iyy="0.002" iyz="0.0000" izz="0.002"/>
    </inertial>
    <visual>
      <origin rpy="0 0 0" xyz="0 0 0"/>
      <geometry>
        <mesh filename="package://golem_description/meshes/l_shoulder_m20.STL"/>
      </geometry>
      <material name="">
        <color rgba="1 0.501960784313725 0.501960784313725 1"/>
      </material>
    </visual>
    <collision>
      <origin rpy="0 0 0" xyz="0 0 0"/>
      <geometry>
        <mesh filename="package://golem_description/meshes/l_shoulder_m20.STL"/>
      </geometry>
    </collision>
  </link>
  <joint name="m20" type="revolute">
    <origin rpy="0.0 0.0 1.5708" xyz="0 0.1225 0.0593"/>
    <parent link="chest"/>
    <child link="l_shoulder_m20"/>
    <axis xyz="0 0 1"/>
    <limit effort="100" lower="-1.14" upper="1.75" velocity="0.1"/>
    <dynamics friction="0.6"/>
  </joint>
  <!-- Left shoulder m21 motor-->
  <link name="l_shoulder_m21">
    <inertial>
      <origin rpy="0 0 0" xyz="0.00429943368445523 -4.92661467177413E-13 0.0397852819427535"/>
      <mass value="0.00839075663685627"/>
      <inertia ixx="0.0002" ixy="0.0" ixz="0.0" iyy="0.0002" iyz="0.0" izz="0.0002"/>
    </inertial>
    <visual>
      <origin rpy="0 0 0" xyz="0 0 0"/>
      <geometry>
        <mesh filename="package://golem_description/meshes/l_shoulder_m21.STL"/>
      </geometry>
      <material name="">
        <color rgba="0.501960784313725 0.501960784313725 0.501960784313725 1"/>
      </material>
    </visual>
    <collision>
      <origin rpy="0 0 0" xyz="0 0 0"/>
      <geometry>
        <mesh filename="package://golem_description/meshes/l_shoulder_m21.STL"/>
      </geometry>
    </collision>
  </link>
  <joint name="m21" type="revolute">
    <origin rpy="-3.1416 0.0 3.1416" xyz="0.212 0.0 0.054396"/>
    <parent link="l_shoulder_m20"/>
    <child link="l_shoulder_m21"/>
    <axis xyz="0 0 1"/>
    <limit effort="100" lower="-3" upper="3" velocity="0.1"/>
    <dynamics friction="0.6"/>
  </joint>
  <!-- Left arm motor -->
  <link name="l_arm">
    <inertial>
      <origin rpy="0 0 0" xyz="0.131360969349986 0.00869049182380505 0.00048707803278325"/>
      <mass value="0.523875208233877"/>
      <inertia ixx="0.002" ixy="0.0000" ixz="0.0000" iyy="0.002" iyz="0.0000" izz="0.002"/>
    </inertial>
    <visual>
      <origin rpy="0 0 0" xyz="0 0 0"/>
      <geometry>
        <mesh filename="package://golem_description/meshes/l_arm.STL"/>
      </geometry>
      <material name="">
        <color rgba="0.501960784313725 1 0.501960784313725 1"/>
      </material>
    </visual>
    <collision>
      <origin rpy="0 0 0" xyz="0 0 0"/>
      <geometry>
        <mesh filename="package://golem_description/meshes/l_arm.STL"/>
      </geometry>
    </collision>
  </link>
  <joint name="m22" type="revolute">
    <origin rpy="3.14159265359 -1.57079632679 0.0" xyz="0.0 0.0 0.06"/>
    <parent link="l_shoulder_m21"/>
    <child link="l_arm"/>
    <axis xyz="0 0 -1"/>
    <limit effort="100.0" lower="-1.55" upper="1.55" velocity="0.1"/>
    <dynamics friction="0.6"/>
  </joint>
  <!-- Left Forearm motor -->
  <link name="l_forearm">
    <inertial>
      <origin rpy="0 0 0" xyz="0.108270232216093 0.0483698597482032 -0.000350351491486045"/>
      <mass value="0.376568906552166"/>
      <inertia ixx="0.001" ixy="0.0000" ixz="0.0000" iyy="0.001" iyz="0.0000" izz="0.002"/>
    </inertial>
    <visual>
      <origin rpy="0 0 -0.785398163397" xyz="0 0 0"/>
      <geometry>
        <mesh filename="package://golem_description/meshes/l_forearm.STL"/>
      </geometry>
      <material name="">
        <color rgba="0.501960784313725 0.501960784313725 1 1"/>
      </material>
    </visual>
    <collision>
      <origin rpy="0 0 -0.785398163397" xyz="0 0 0"/>
      <geometry>
        <mesh filename="package://golem_description/meshes/l_forearm.STL"/>
      </geometry>
    </collision>
  </link>
  <joint name="m23" type="revolute">
    <origin rpy="0.0 0.0 1.57079632679" xyz="0.24895 0.05978 0.0"/>
    <parent link="l_arm"/>
    <child link="l_forearm"/>
    <axis xyz="0 0 -1"/>
    <limit effort="100.0" lower="-1.55" upper="1.55" velocity="0.1"/>
    <dynamics friction="0.6"/>
  </joint>
  <!-- Left wrist motor -->
  <link name="l_wrist">
    <inertial>
      <origin rpy="0 0 0" xyz="0.00499371660552256 -0.00176269973546561 0.0531563838624657"/>
      <mass value="0.0311387724661603"/>
      <inertia ixx="0.00003" ixy="0.0000" ixz="0.0000" iyy="0.00005" iyz="0.0000" izz="0.00003"/>
    </inertial>
    <visual>
      <origin rpy="0.0 0.0 0.0" xyz="0.0 0.0 0.0"/>
      <geometry>
        <mesh filename="package://golem_description/meshes/l_wrist.STL"/>
      </geometry>
      <material name="">
        <color rgba="1 0.501960784313725 1 1"/>
      </material>
    </visual>
    <collision>
      <origin rpy="0.0 0.0 0.0" xyz="0.0 0.0 0.0"/>
      <geometry>
        <mesh filename="package://golem_description/meshes/l_wrist.STL"/>
      </geometry>
    </collision>
  </link>
  <joint name="m24" type="revolute">
    <origin rpy="1.57079632679 0.0 1.57079632679" xyz="0.2 -0.034 0.0"/>
    <parent link="l_forearm"/>
    <child link="l_wrist"/>
    <axis xyz="0 0 1"/>
    <limit effort="3.7" lower="-1.67" upper="1.67" velocity="0.1"/>
    <dynamics friction="0.6"/>
  </joint>
  <!-- Left virtual joint to indicate center of the gripper -->
  <link name="l_eef"/>
  <joint name="l_eef_end" type="fixed">
    <origin rpy="-1.57079632679 -1.57079632679 -1.57079632679" xyz="0.0 0.0 0.2"/>
    <parent link="l_wrist"/>
    <child link="l_eef"/>
  </joint>
  <!-- Ledt gripper m25 motor -->
  <link name="l_gripper_m25">
    <inertial>
      <origin rpy="0 0 0" xyz="0.0668949493902099 -0.00886945271498052 0.00431771664598046"/>
      <mass value="0.0609094064539814"/>
      <inertia ixx="0.00004" ixy="0.0000" ixz="0.0000" iyy="0.00020" iyz="0.0000" izz="0.00020"/>
    </inertial>
    <visual>
      <origin rpy="0 0 0" xyz="0 0 0"/>
      <geometry>
        <mesh filename="package://golem_description/meshes/l_gripper_m25.STL"/>
      </geometry>
      <material name="">
        <color rgba="0.792156862745098 0.819607843137255 0.933333333333333 1"/>
      </material>
    </visual>
    <collision>
      <origin rpy="0 0 0" xyz="0 0 0"/>
      <geometry>
        <mesh filename="package://golem_description/meshes/l_gripper_m25.STL"/>
      </geometry>
    </collision>
  </link>
  <joint name="m25" type="revolute">
    <origin rpy="-1.57079632679 -1.57079632679 -1.57079632679" xyz="0.0 0.010755 0.10471"/>
    <parent link="l_wrist"/>
    <child link="l_gripper_m25"/>
    <axis xyz="0 0 -1"/>
    <limit effort="100.0" lower="0" upper="1.6" velocity="0.1"/>
    <dynamics friction="0.6"/>
  </joint>
  <!-- Left gripper m27 motor -->
  <link name="l_gripper_m27">
    <inertial>
      <origin rpy="0 0 0" xyz="0.0668949493902098 0.00886945271498041 0.00431771664598063"/>
      <mass value="0.0609094064539813"/>
      <inertia ixx="0.0002" ixy="0.0000" ixz="0.0000" iyy="0.0002" iyz="0.0000" izz="0.0002"/>
    </inertial>
    <visual>
      <origin rpy="0 0 0" xyz="0 0 0"/>
      <geometry>
        <mesh filename="package://golem_description/meshes/l_gripper_m27.STL"/>
      </geometry>
      <material name="">
        <color rgba="0.792156862745098 0.819607843137255 0.933333333333333 1"/>
      </material>
    </visual>
    <collision>
      <origin rpy="0 0 0" xyz="0 0 0"/>
      <geometry>
        <mesh filename="package://golem_description/meshes/l_gripper_m27.STL"/>
      </geometry>
    </collision>
  </link>
  <joint name="m27" type="revolute">
    <origin rpy="-1.57079632679 0.0 -1.57079632679" xyz="0.003 -0.021173 0.10255"/>
    <parent link="l_wrist"/>
    <child link="l_gripper_m27"/>
    <axis xyz="0 0 -1"/>
    <limit effort="100.0" lower="0" upper="1.6" velocity="0.1"/>
    <dynamics friction="0.6"/>
  </joint>
  <!-- Transmission elements-->
  <!-- Necessary for the ros_control simulation -->
  <!--Body-->
  <transmission name="body_transmission">
    <type>transmission_interface/SimpleTransmission</type>
    <joint name="mb">
      <hardwareInterface>EffortJointInterface</hardwareInterface>
    </joint>
    <actuator name="body_motor">
      <hardwareInterface>EffortJointInterface</hardwareInterface>
      <mechanicalReduction>1</mechanicalReduction>
    </actuator>
  </transmission>
  <!--Chest-->
  <transmission name="chest_transmission">
    <type>transmission_interface/SimpleTransmission</type>
    <joint name="m0">
      <hardwareInterface>EffortJointInterface</hardwareInterface>
    </joint>
    <actuator name="chest_motor">
      <hardwareInterface>EffortJointInterface</hardwareInterface>
      <mechanicalReduction>1</mechanicalReduction>
    </actuator>
  </transmission>
  <!--Head 1-->
  <transmission name="head1_transmission">
    <type>transmission_interface/SimpleTransmission</type>
    <joint name="m1">
      <hardwareInterface>EffortJointInterface</hardwareInterface>
    </joint>
    <actuator name="head1_motor">
      <hardwareInterface>EffortJointInterface</hardwareInterface>
      <mechanicalReduction>0.01</mechanicalReduction>
    </actuator>
  </transmission>
  <!-- Head 2 -->
  <transmission name="head2_transmission">
    <type>transmission_interface/SimpleTransmission</type>
    <joint name="m2">
      <hardwareInterface>EffortJointInterface</hardwareInterface>
    </joint>
    <actuator name="head2_motor">
      <hardwareInterface>EffortJointInterface</hardwareInterface>
      <mechanicalReduction>50.0</mechanicalReduction>
    </actuator>
  </transmission>
  <!-- Right shoulder motor 10 -->
  <transmission name="r_shoulder10_transmission">
    <type>transmission_interface/SimpleTransmission</type>
    <joint name="m10">
      <hardwareInterface>EffortJointInterface</hardwareInterface>
    </joint>
    <actuator name="r_shoulder10_motor">
      <hardwareInterface>EffortJointInterface</hardwareInterface>
      <mechanicalReduction>1</mechanicalReduction>
    </actuator>
  </transmission>
  <!-- Right shoulder motor 11 -->
  <transmission name="r_shoulder11_transmission">
    <type>transmission_interface/SimpleTransmission</type>
    <joint name="m11">
      <hardwareInterface>EffortJointInterface</hardwareInterface>
    </joint>
    <actuator name="r_shoulder11_motor">
      <hardwareInterface>EffortJointInterface</hardwareInterface>
      <mechanicalReduction>1</mechanicalReduction>
    </actuator>
  </transmission>
  <!-- Right arm -->
  <transmission name="r_arm_transmission">
    <type>transmission_interface/SimpleTransmission</type>
    <joint name="m12">
      <hardwareInterface>EffortJointInterface</hardwareInterface>
    </joint>
    <actuator name="r_arm_motor">
      <hardwareInterface>EffortJointInterface</hardwareInterface>
      <mechanicalReduction>1</mechanicalReduction>
    </actuator>
  </transmission>
  <!-- Right forearm -->
  <transmission name="r_forearm_transmission">
    <type>transmission_interface/SimpleTransmission</type>
    <joint name="m13">
      <hardwareInterface>EffortJointInterface</hardwareInterface>
    </joint>
    <actuator name="r_forearm_motor">
      <hardwareInterface>EffortJointInterface</hardwareInterface>
      <mechanicalReduction>1</mechanicalReduction>
    </actuator>
  </transmission>
  <!-- Right wrist -->
  <transmission name="r_wrist_transmission">
    <type>transmission_interface/SimpleTransmission</type>
    <joint name="m14">
      <hardwareInterface>EffortJointInterface</hardwareInterface>
    </joint>
    <actuator name="r_wrist_motor">
      <hardwareInterface>EffortJointInterface</hardwareInterface>
      <mechanicalReduction>1</mechanicalReduction>
    </actuator>
  </transmission>
  <!-- Right gripper motor 15 -->
  <transmission name="r_gripper15_transmission">
    <type>transmission_interface/SimpleTransmission</type>
    <joint name="m15">
      <hardwareInterface>EffortJointInterface</hardwareInterface>
    </joint>
    <actuator name="r_gripper15_motor">
      <hardwareInterface>EffortJointInterface</hardwareInterface>
      <mechanicalReduction>1</mechanicalReduction>
    </actuator>
  </transmission>
  <!-- Right gripper motor 17 -->
  <transmission name="r_gripper17_transmission">
    <type>transmission_interface/SimpleTransmission</type>
    <joint name="m17">
      <hardwareInterface>EffortJointInterface</hardwareInterface>
    </joint>
    <actuator name="r_gripper17_motor">
      <hardwareInterface>EffortJointInterface</hardwareInterface>
      <mechanicalReduction>1</mechanicalReduction>
    </actuator>
  </transmission>
  <!-- Left shoulder motor 20 -->
  <transmission name="l_shoulder20_transmission">
    <type>transmission_interface/SimpleTransmission</type>
    <joint name="m20">
      <hardwareInterface>EffortJointInterface</hardwareInterface>
    </joint>
    <actuator name="l_shoulder20_motor">
      <hardwareInterface>EffortJointInterface</hardwareInterface>
      <mechanicalReduction>1</mechanicalReduction>
    </actuator>
  </transmission>
  <!-- Left shoulder motor 21 -->
  <transmission name="l_shoulder21_transmission">
    <type>transmission_interface/SimpleTransmission</type>
    <joint name="m21">
      <hardwareInterface>EffortJointInterface</hardwareInterface>
    </joint>
    <actuator name="l_shoulder21_motor">
      <hardwareInterface>EffortJointInterface</hardwareInterface>
      <mechanicalReduction>1</mechanicalReduction>
    </actuator>
  </transmission>
  <!-- Left arm -->
  <transmission name="l_arm_transmission">
    <type>transmission_interface/SimpleTransmission</type>
    <joint name="m22">
      <hardwareInterface>EffortJointInterface</hardwareInterface>
    </joint>
    <actuator name="l_arm_motor">
      <hardwareInterface>EffortJointInterface</hardwareInterface>
      <mechanicalReduction>1</mechanicalReduction>
    </actuator>
  </transmission>
  <!-- Left forearm -->
  <transmission name="l_forearm_transmission">
    <type>transmission_interface/SimpleTransmission</type>
    <joint name="m23">
      <hardwareInterface>EffortJointInterface</hardwareInterface>
    </joint>
    <actuator name="l_forearm_motor">
      <hardwareInterface>EffortJointInterface</hardwareInterface>
      <mechanicalReduction>1</mechanicalReduction>
    </actuator>
  </transmission>
  <!-- Left wrist -->
  <transmission name="l_wrist_transmission">
    <type>transmission_interface/SimpleTransmission</type>
    <joint name="m24">
      <hardwareInterface>EffortJointInterface</hardwareInterface>
    </joint>
    <actuator name="l_wrist_motor">
      <hardwareInterface>EffortJointInterface</hardwareInterface>
      <mechanicalReduction>1</mechanicalReduction>
    </actuator>
  </transmission>
  <!-- Left gripper motor 25 -->
  <transmission name="l_gripper25_transmission">
    <type>transmission_interface/SimpleTransmission</type>
    <joint name="m25">
      <hardwareInterface>EffortJointInterface</hardwareInterface>
    </joint>
    <actuator name="l_gripper25_motor">
      <hardwareInterface>EffortJointInterface</hardwareInterface>
      <mechanicalReduction>1</mechanicalReduction>
    </actuator>
  </transmission>
  <!-- Left gripper motor 27 -->
  <transmission name="l_gripper27_transmission">
    <type>transmission_interface/SimpleTransmission</type>
    <joint name="m27">
      <hardwareInterface>EffortJointInterface</hardwareInterface>
    </joint>
    <actuator name="l_gripper27_motor">
      <hardwareInterface>EffortJointInterface</hardwareInterface>
      <mechanicalReduction>1</mechanicalReduction>
    </actuator>
  </transmission>
</robot>

